Workbook

Sheet Products
A1: Brand | B1: Product_Name | C1: Category | D1: Price | E1: Sizes_Available | F1: Product_URL | G1: Notes
A2: Levi’s | B2: Levi’s Men Pure Cotton V-Neck Short Sleeve T-shirt | C2: T-Shirts | D2: 649 | E2: S, M, L, XL | F2: https://www.myntra.com/lounge-tshirts/levis/levis-men-pure-cotton-v-neck-short-sleeve-tshirt/12027434/buy | G2: Pure Cotton, V-Neck, Regular Fit, Lounge Wear
A3: Levi’s | B3: Levi’s Men Soft Pure Cotton Round Neck Half Sleeve T-shirt | C3: T-Shirts | D3: 649 | E3: S, M, L, XL | F3: https://www.myntra.com/lounge-tshirts/levis/levis-men-soft-pure-cotton-round-neck-half-sleeve-tshirt/12027436/buy | G3: Pure Cotton, Round Neck, Regular Fit
A4: Adidas | B4: Adidas Brand Logo Print Detail Sports T-Shirt | C4: T-Shirts | D4: 829 | E4: XS, S, M, L, XL, XXL | F4: https://www.myntra.com/tshirts/adidas/adidas-brand-logo-print-detail-sports-t-shirt/29564784/buy | G4: Logo print sports tee, casual fit
A5: Puma | B5: Puma Men Slim Fit Polo T-Shirt | C5: T-Shirts | D5: 1699 | E5: XS, S, M, L, XL, XXL, 3XL, 4XL | F5: https://www.myntra.com/tshirts/puma/puma-men-slim-fit-polo-t-shirt/30850259/buy | G5: Slim fit, polo collar, cotton blend
A6: H&M | B6: H&M Men White Solid Cotton Pure Cotton T-shirt Regular Fit | C6: T-Shirts | D6: 499 | E6: XS, S, M, L, XL, XXL | F6: https://www.myntra.com/tshirts/h%26m/hm-men-white-solid-cotton-pure-cotton-t-shirt-regular-fit/11468714/buy | G6: Regular Fit, Pure Cotton
A7: Roadster | B7: The Roadster Lifestyle Co Men Navy Blue Solid Polo Collar T-shirt | C7: T-Shirts | D7: 599 | E7: S, M, L, XL | F7: https://www.myntra.com/tshirts/roadster/the-roadster-lifestyle-co-men-navy-blue-solid-polo-collar-t-shirt/10943272/buy | G7: Polo Collar, Regular Fit
A8: Roadster | B8: The Roadster Life Co Polo Collar T-Shirt | C8: T-Shirts | D8: 899 | E8: XS, S, M, L, XL, XXL, 3XL | F8: https://www.myntra.com/tshirts/roadster/the-roadster-life-co-polo-collar-t-shirt/1996801/buy | G8: Polo Collar, Cotton, Regular Fit
A9: Mast & Harbour | B9: Mast & Harbour Men Coral Pink Striped Polo Collar Cotton T-shirt | C9: T-Shirts | D9: 1299 | E9: S, M, L, XL | F9: https://www.myntra.com/tshirts/mast+%26+harbour/mast--harbour-men-coral-pink-striped-polo-collar-cotton-t-shirt/4149433/buy | G9: Polo Collar, Cotton, Regular Fit
A10: WROGN | B10: WROGN Men White & Blue Printed Slim Fit Polo Collar Cotton T-shirt | C10: T-Shirts | D10: 799 | E10: S, M, L, XL, XXL | F10: https://www.myntra.com/tshirts/wrogn/wrogn-men-white--blue-printed-slim-fit-polo-collar--cotton-t-shirt/11363324/buy | G10: Slim Fit, Polo Collar, Cotton
A11: HERE & NOW | B11: HERE & NOW Round Neck Long Sleeves Regular Fit T-Shirt | C11: T-Shirts | D11: 1299 | E11: M, L, XL | F11: https://www.myntra.com/tshirts/here%26now/herenow-round-neck-long-sleeves-regular-fit-t-shirt/37686350/buy | G11: Round Neck, Long Sleeves, Regular Fit
A12: Levi’s | B12: Levi’s Pure Cotton Slim Fit Casual Shirt | C12: Shirts | D12: 1899 | E12: XS, S, M, L, XL, XXL | F12: https://www.myntra.com/shirts/levis/levis-pure-cotton-slim-fit-casual-shirt/32257172/buy | G12: Slim Fit, Pure Cotton
A13: Levi’s | B13: Levi’s Pure Cotton Solid Slim Fit Opaque Casual Shirt | C13: Shirts | D13: 1899 | E13: S, M, L, XL, XXL, 3XL | F13: https://www.myntra.com/shirts/levis/levis-pure-cotton-solid-slim-fit-opaque-casual-shirt/25756898/buy | G13: Slim Fit, Opaque
... A31: H&M | B31: H&M Cropped Vest Top | C31: Tops | D31: 1299 | E31: XS, S, M, L, XL | F31: https://www.myntra.com/tops/h%26m/hm-cropped-vest-top/21678936/buy | G31: Cropped

Sheet Size_Charts
A1: Brand | B1: Category | C1: Size | D1: Chest_CM | E1: Waist_CM | F1: Length_CM | G1: Source_URL
A2: Levi’s | B2: T-Shirts | C2: S | D2: 97 | F2: 68.1 | G2: https://www.myntra.com/lounge-tshirts/levis/levis-men-pure-cotton-v-neck-short-sleeve-tshirt/12027434/buy
A3: Levi’s | B3: T-Shirts | C3: M | D3: 101.9 | F3: 70.6 | G3: https://www.myntra.com/lounge-tshirts/levis/levis-men-pure-cotton-v-neck-short-sleeve-tshirt/12027434/buy
A4: Levi’s | B4: T-Shirts | C4: L | D4: 106.9 | F4: 72.9 | G4: https://www.myntra.com/lounge-tshirts/levis/levis-men-pure-cotton-v-neck-short-sleeve-tshirt/12027434/buy
A5: Levi’s | B5: T-Shirts | C5: XL | D5: 112 | F5: 75.4 | G5: https://www.myntra.com/lounge-tshirts/levis/levis-men-pure-cotton-v-neck-short-sleeve-tshirt/12027434/buy
A6: Levi’s | B6: T-Shirts | C6: S | D6: 97 | F6: 68.1 | G6: https://www.myntra.com/lounge-tshirts/levis/levis-men-soft-pure-cotton-round-neck-half-sleeve-tshirt/12027436/buy
A7: Levi’s | B7: T-Shirts | C7: M | D7: 101.9 | F7: 70.6 | G7: https://www.myntra.com/lounge-tshirts/levis/levis-men-soft-pure-cotton-round-neck-half-sleeve-tshirt/12027436/buy
A8: Levi’s | B8: T-Shirts | C8: L | D8: 106.9 | F8: 72.9 | G8: https://www.myntra.com/lounge-tshirts/levis/levis-men-soft-pure-cotton-round-neck-half-sleeve-tshirt/12027436/buy
A9: Levi’s | B9: T-Shirts | C9: XL | D9: 112 | F9: 75.4 | G9: https://www.myntra.com/lounge-tshirts/levis/levis-men-soft-pure-cotton-round-neck-half-sleeve-tshirt/12027436/buy
A10: Adidas | B10: T-Shirts | C10: XS | D10: 96 | E10: N/A | F10: 70.4 | G10: https://www.myntra.com/tshirts/adidas/adidas-brand-logo-print-detail-sports-t-shirt/29564784/buy
A11: Adidas | B11: T-Shirts | C11: S | D11: 102.1 | E11: N/A | F11: 72.6 | G11: https://www.myntra.com/tshirts/adidas/adidas-brand-logo-print-detail-sports-t-shirt/29564784/buy
A12: Adidas | B12: T-Shirts | C12: M | D12: 109.9 | E12: N/A | F12: 74.9 | G12: https://www.myntra.com/tshirts/adidas/adidas-brand-logo-print-detail-sports-t-shirt/29564784/buy
A13: Adidas | B13: T-Shirts | C13: L | D13: 118.1 | E13: N/A | F13: 77.2 | G13: https://www.myntra.com/tshirts/adidas/adidas-brand-logo-print-detail-sports-t-shirt/29564784/buy
A14: Adidas | B14: T-Shirts | C14: XL | D14: 128 | E14: N/A | F14: 79.5 | G14: https://www.myntra.com/tshirts/adidas/adidas-brand-logo-print-detail-sports-t-shirt/29564784/buy
A15: Adidas | B15: T-Shirts | C15: XXL | D15: 139.9 | E15: N/A | F15: 82.3 | G15: https://www.myntra.com/tshirts/adidas/adidas-brand-logo-print-detail-sports-t-shirt/29564784/buy
A16: Puma | B16: T-Shirts | C16: XS | D16: 85.1 | E16: N/A | F16: 70.9 | G16: https://www.myntra.com/tshirts/puma/puma-men-slim-fit-polo-t-shirt/30850259/buy
A17: Puma | B17: T-Shirts | C17: S | D17: 93 | E17: N/A | F17: 72.1 | G17: https://www.myntra.com/tshirts/puma/puma-men-slim-fit-polo-t-shirt/30850259/buy
A18: Puma | B18: T-Shirts | C18: M | D18: 101.1 | E18: N/A | F18: 72.9 | G18: https://www.myntra.com/tshirts/puma/puma-men-slim-fit-polo-t-shirt/30850259/buy
A19: Puma | B19: T-Shirts | C19: L | D19: 109 | E19: N/A | F19: 74.9 | G19: https://www.myntra.com/tshirts/puma/puma-men-slim-fit-polo-t-shirt/30850259/buy
A20: Puma | B20: T-Shirts | C20: XL | D20: 119.1 | E20: N/A | F20: 77 | G20: https://www.myntra.com/tshirts/puma/puma-men-slim-fit-polo-t-shirt/30850259/buy
A21: Puma | B21: T-Shirts | C21: XXL | D21: 129 | E21: N/A | F21: 79 | G21: https://www.myntra.com/tshirts/puma/puma-men-slim-fit-polo-t-shirt/30850259/buy
... A23: Puma | B23: T-Shirts | C23: 4XL | D23: 149.1 | E23: N/A | F23: 83.8 | G23: https://www.myntra.com/tshirts/puma/puma-men-slim-fit-polo-t-shirt/30850259/buy
A24: H&M | B24: T-Shirts | C24: XS | D24: 83.8 | G24: https://www.myntra.com/tshirts/h%26m/hm-men-white-solid-cotton-pure-cotton-t-shirt-regular-fit/11468714/buy
A25: H&M | B25: T-Shirts | C25: S | D25: 92.2 | G25: https://www.myntra.com/tshirts/h%26m/hm-men-white-solid-cotton-pure-cotton-t-shirt-regular-fit/11468714/buy
A26: H&M | B26: T-Shirts | C26: M | D26: 100.3 | G26: https://www.myntra.com/tshirts/h%26m/hm-men-white-solid-cotton-pure-cotton-t-shirt-regular-fit/11468714/buy
A27: H&M | B27: T-Shirts | C27: L | D27: 108 | G27: https://www.myntra.com/tshirts/h%26m/hm-men-white-solid-cotton-pure-cotton-t-shirt-regular-fit/11468714/buy
A28: H&M | B28: T-Shirts | C28: XL | D28: 115.6 | G28: https://www.myntra.com/tshirts/h%26m/hm-men-white-solid-cotton-pure-cotton-t-shirt-regular-fit/11468714/buy
A29: H&M | B29: T-Shirts | C29: XXL | D29: 124 | G29: https://www.myntra.com/tshirts/h%26m/hm-men-white-solid-cotton-pure-cotton-t-shirt-regular-fit/11468714/buy
A30: Roadster | B30: T-Shirts | C30: XS | D30: 91.4 | E30: 91.4 | F30: 68.6 | G30: https://www.myntra.com/tshirts/roadster/the-roadster-life-co-polo-collar-t-shirt/1996801/buy
A31: Roadster | B31: T-Shirts | C31: S | D31: 96.5 | E31: 96.5 | F31: 69.8 | G31: https://www.myntra.com/tshirts/roadster/the-roadster-life-co-polo-collar-t-shirt/1996801/buy
A32: Roadster | B32: T-Shirts | C32: M | D32: 101.6 | E32: 101.6 | F32: 71.1 | G32: https://www.myntra.com/tshirts/roadster/the-roadster-life-co-polo-collar-t-shirt/1996801/buy
A33: Roadster | B33: T-Shirts | C33: L | D33: 106.7 | E33: 106.7 | F33: 72.4 | G33: https://www.myntra.com/tshirts/roadster/the-roadster-life-co-polo-collar-t-shirt/1996801/buy
A34: Roadster | B34: T-Shirts | C34: XL | D34: 113 | E34: 113 | F34: 73.7 | G34: https://www.myntra.com/tshirts/roadster/the-roadster-life-co-polo-collar-t-shirt/1996801/buy
A35: Roadster | B35: T-Shirts | C35: XXL | D35: 119.4 | E35: 119.4 | F35: 74.9 | G35: https://www.myntra.com/tshirts/roadster/the-roadster-life-co-polo-collar-t-shirt/1996801/buy
A36: Roadster | B36: T-Shirts | C36: 3XL | D36: 127 | E36: 127 | F36: 76.2 | G36: https://www.myntra.com/tshirts/roadster/the-roadster-life-co-polo-collar-t-shirt/1996801/buy
A37: Roadster | B37: T-Shirts | C37: S | D37: 96.5 | E37: 96.5 | F37: 69.8 | G37: https://www.myntra.com/tshirts/roadster/the-roadster-lifestyle-co-men-navy-blue-solid-polo-collar-t-shirt/10943272/buy
A38: Roadster | B38: T-Shirts | C38: M | D38: 101.6 | E38: 101.6 | F38: 71.1 | G38: https://www.myntra.com/tshirts/roadster/the-roadster-lifestyle-co-men-navy-blue-solid-polo-collar-t-shirt/10943272/buy
A39: Roadster | B39: T-Shirts | C39: L | D39: 106.7 | E39: 106.7 | F39: 72.4 | G39: https://www.myntra.com/tshirts/roadster/the-roadster-lifestyle-co-men-navy-blue-solid-polo-collar-t-shirt/10943272/buy
A40: Roadster | B40: T-Shirts | C40: XL | D40: 113 | E40: 113 | F40: 73.7 | G40: https://www.myntra.com/tshirts/roadster/the-roadster-lifestyle-co-men-navy-blue-solid-polo-collar-t-shirt/10943272/buy
A41: Mast & Harbour | B41: T-Shirts | C41: S | D41: 96.5 | F41: 66 | G41: https://www.myntra.com/tshirts/mast+%26+harbour/mast--harbour-men-coral-pink-striped-polo-collar-cotton-t-shirt/4149433/buy
...

Sheet Reviews
A1: Brand | B1: Product_Name | C1: Review_Text | D1: Rating | E1: Size_Mentioned | F1: Fit_Feedback
A2: Levi’s | B2: Levi’s Men Pure Cotton V-Neck Short Sleeve T-shirt | C2: Good quality, very comfortable and smooth. Bought for my dad and it fits right, but XXL should be available for elders. | D2: 4 | E2: Yes | F2: True to Size
A3: Levi’s | B3: Levi’s Men Pure Cotton V-Neck Short Sleeve T-shirt | C3: Super soft pure cotton with premium feel. Fit is just right, not too tight or loose, and holds well after washes. | D3: 5 | E3: No | F3: True to Size
A4: Levi’s | B4: Levi’s Men Pure Cotton V-Neck Short Sleeve T-shirt | C4: Perfect cotton thickness, color matches pictures and the fit is perfect. Loved the product. | D4: 5 | E4: No | F4: Perfect Fit
A5: Levi’s | B5: Levi’s Men Soft Pure Cotton Round Neck Half Sleeve T-shirt | C5: Quality is outstanding with soft and comfortable fabric. Fit is perfect, true to size, and looks good even after multiple washes. | D5: 5 | E5: No | F5: True to Size
A6: Levi’s | B6: Levi’s Men Soft Pure Cotton Round Neck Half Sleeve T-shirt | C6: Fabric feels soft and breathable. Fit is mostly accurate, neither too tight nor too loose. Good value for money. | D6: 4 | E6: No | F6: True to Size
A7: Levi’s | B7: Levi’s Men Soft Pure Cotton Round Neck Half Sleeve T-shirt | C7: Size S is perfect in length but shoulder and chest are too big, needed alteration. | D7: 3 | E7: Yes | F7: Runs Large
A8: Adidas | B8: Adidas Brand Logo Print Detail Sports T-Shirt | C8: “Comfortable tee with bold logo. Fit exactly as expected.” | D8: 5 | E8: No | F8: True to Size
A9: Adidas | B9: Adidas Brand Logo Print Detail Sports T-Shirt | C9: “Ordered M, true fit, breathable.” | D9: 5 | E9: Yes | F9: True to Size
A10: Adidas | B10: Adidas Brand Logo Print Detail Sports T-Shirt | C10: “A bit loose around the waist, but overall good.” | D10: 4 | E10: No | F10: Runs Large
A11: Puma | B11: Puma Men Slim Fit Polo T-Shirt | C11: Soft breathable fabric, true to size fit. | D11: 5 | E11: No | F11: True to Size
A12: Puma | B12: Puma Men Slim Fit Polo T-Shirt | C12: Excellent quality, snug shoulders, perfect fit. | D12: 5 | E12: No | F12: True to Size
A13: Puma | B13: Puma Men Slim Fit Polo T-Shirt | C13: Material blend not pure cotton, not as expected. | D13: 1 | E13: No | F13: True to Size
... A91: H&M | B91: H&M Cropped Vest Top | C91: Stylish, comfortable, great everyday wear. | D91: 5 | E91: No | F91: True to Size
A95: Brand | B95: Review_text | C95: Fit_tag
A96: Puma | B96: Soft breathable fabric, true to size fit. | C96: True to Size
A97: Puma | B97: Excellent quality, snug shoulders, perfect fit. | C97: True to Size
A98: Puma | B98: Material blend not pure cotton, not as expected. | C98: Not Mentioned
A99: Puma | B99: XL size is too large. | C99: Runs Large
A100: Puma | B100: Soft, thin but warm, good for Delhi winter. | C100: Not Mentioned
A101: Adidas | B101: “Comfortable tee with bold logo. Fit exactly as expected.” | C101: True to Size
A102: Adidas | B102: “Ordered M, true fit, breathable.” | C102: True to Size
A103: Adidas | B103: “A bit loose around the waist, but overall good.” | C103: Runs Large
A104: Adidas | B104: Great fit, highly recommend. | C104: True to Size
A105: Adidas | B105: Fit is good but material is thin. | C105: True to Size
A106: Roadster | B106: Material is good but the fit runs a little small, order one size up. | C106: Runs Small
... A110: Roadster | B110: Stretchy fabric makes bust look bigger, returned. | C110: Runs Large

Sheet Comparitive_analysis
A1: Feature | B1: Myntra | C1: AJIO | D1: Amazon Fashion | E1: Zara | F1: H&M
A2: Size guide visibility | B2: Static link | C2: Static link | D2: Inline + expandable | E2: Detailed page | F2: Detailed page
A3: Size recommendation | B3: ❌ | C3: ❌ | D3: ✅ “Recommended size” | E3: ❌ | F3: ❌
A4: Fit feedback from reviews | B4: Buried (unstructured) | C4: Buried (unstructured) | D4: ✅ “Customers say runs small/large” | E4: ❌ | F4: ❌
A5: Brand-specific sizing notes | B5: ❌ | C5: ❌ | D5: Partial | E5: ✅ | F5: Partial
A6: Size comparison across brands | B6: ❌ | C6: ❌ | D6: ❌ | E6: ❌ | F6: ❌
A7: Virtual try-on | B7: ❌ | C7: ❌ | D7: ❌ | E7: ❌ | F7: ❌

Sheet Brand_size_analysis
A1: Brand | B1: Size | C1: Chest_CM
A2: Levi’s | B2: S | C2: 97
A3: Levi’s | B3: M | C3: 101.9
A4: Levi’s | B4: L | C4: 106.9
A5: Levi’s | B5: XL | C5: 112
A6: Levi’s | B6: S | C6: 97
A7: Levi’s | B7: M | C7: 101.9
A8: Levi’s | B8: L | C8: 106.9
A9: Levi’s | B9: XL | C9: 112
A10: Adidas | B10: XS | C10: 96
A11: Adidas | B11: S | C11: 102.1
A12: Adidas | B12: M | C12: 109.9
A13: Adidas | B13: L | C13: 118.1
... A159: H&M | B159: XL | C159: 112.8

Sheet Brand_size_avg
A1: Brand | B1: S | C1: M | D1: L | E1: XL | F1: XXL | G1: 3XL | H1: 4XL | I1: Std_Dev | J1: CV | K1: Mean_Chest | L1: Consistency_Flag
A2: Levi’s | B2: =AVERAGEIFS(Brand_size_analysis!$C:$C, Brand_size_analysis!$A:$A, $A2, Brand_size_analysis!$B:$B, B$1) -> 99.72 | C2: =AVERAGEIFS(Brand_size_analysis!$C:$C, Brand_size_analysis!$A:$A, $A2, Brand_size_analysis!$B:$B, C$1) -> 105.54 | D2: =AVERAGEIFS(Brand_size_analysis!$C:$C, Brand_size_analysis!$A:$A, $A2, Brand_size_analysis!$B:$B, D$1) -> 111.6 | E2: =AVERAGEIFS(Brand_size_analysis!$C:$C, Brand_size_analysis!$A:$A, $A2, Brand_size_analysis!$B:$B, E$1) -> 118.2 | F2: =AVERAGEIFS(Brand_size_analysis!$C:$C, Brand_size_analysis!$A:$A, $A2, Brand_size_analysis!$B:$B, F$1) -> 132.7 | I2: =_xlfn.STDEV.S(B2:H2) -> 12.723762 | J2: =I2/K2 -> 0.11205229 | K2: =AVERAGE(B2:H2) -> 113.552 | L2: =IF(J2>0.15,"High Inconsistency","Acceptable") -> Acceptable
A3: Adidas | B3: =AVERAGEIFS(Brand_size_analysis!$C:$C, Brand_size_analysis!$A:$A, $A3, Brand_size_analysis!$B:$B, B$1) -> 91.05 | C3: =AVERAGEIFS(Brand_size_analysis!$C:$C, Brand_size_analysis!$A:$A, $A3, Brand_size_analysis!$B:$B, C$1) -> 98 | D3: =AVERAGEIFS(Brand_size_analysis!$C:$C, Brand_size_analysis!$A:$A, $A3, Brand_size_analysis!$B:$B, D$1) -> 105.55 | E3: =AVERAGEIFS(Brand_size_analysis!$C:$C, Brand_size_analysis!$A:$A, $A3, Brand_size_analysis!$B:$B, E$1) -> 114.55 | F3: =AVERAGEIFS(Brand_size_analysis!$C:$C, Brand_size_analysis!$A:$A, $A3, Brand_size_analysis!$B:$B, F$1) -> 124.95 | I3: =_xlfn.STDEV.S(B3:H3) -> 13.384207 | J3: =I3/K3 -> 0.12529683 | K3: =AVERAGE(B3:H3) -> 106.82 | L3: =IF(J3>0.15,"High Inconsistency","Acceptable") -> Acceptable
A4: Puma | B4: =AVERAGEIFS(Brand_size_analysis!$C:$C, Brand_size_analysis!$A:$A, $A4, Brand_size_analysis!$B:$B, B$1) -> 91.033333 | C4: =AVERAGEIFS(Brand_size_analysis!$C:$C, Brand_size_analysis!$A:$A, $A4, Brand_size_analysis!$B:$B, C$1) -> 98.033333 | D4: =AVERAGEIFS(Brand_size_analysis!$C:$C, Brand_size_analysis!$A:$A, $A4, Brand_size_analysis!$B:$B, D$1) -> 105 | E4: =AVERAGEIFS(Brand_size_analysis!$C:$C, Brand_size_analysis!$A:$A, $A4, Brand_size_analysis!$B:$B, E$1) -> 113.36667 | F4: =AVERAGEIFS(Brand_size_analysis!$C:$C, Brand_size_analysis!$A:$A, $A4, Brand_size_analysis!$B:$B, F$1) -> 122 | G4: =AVERAGEIFS(Brand_size_analysis!$C:$C, Brand_size_analysis!$A:$A, $A4, Brand_size_analysis!$B:$B, G$1) -> 138.9 | H4: =AVERAGEIFS(Brand_size_analysis!$C:$C, Brand_size_analysis!$A:$A, $A4, Brand_size_analysis!$B:$B, H$1) -> 149.1 | I4: =_xlfn.STDEV.S(B4:H4) -> 21.314599 | J4: =I4/K4 -> 0.18252521 | K4: =AVERAGE(B4:H4) -> 116.77619 | L4: =IF(J4>0.15,"High Inconsistency","Acceptable") -> High Inconsistency
A5: H&M | B5: =AVERAGEIFS(Brand_size_analysis!$C:$C, Brand_size_analysis!$A:$A, $A5, Brand_size_analysis!$B:$B, B$1) -> 88.4 | C5: =AVERAGEIFS(Brand_size_analysis!$C:$C, Brand_size_analysis!$A:$A, $A5, Brand_size_analysis!$B:$B, C$1) -> 96.325 | D5: =AVERAGEIFS(Brand_size_analysis!$C:$C, Brand_size_analysis!$A:$A, $A5, Brand_size_analysis!$B:$B, D$1) -> 104.85 | E5: =AVERAGEIFS(Brand_size_analysis!$C:$C, Brand_size_analysis!$A:$A, $A5, Brand_size_analysis!$B:$B, E$1) -> 113 | F5: =AVERAGEIFS(Brand_size_analysis!$C:$C, Brand_size_analysis!$A:$A, $A5, Brand_size_analysis!$B:$B, F$1) -> 121.23333 | I5: =_xlfn.STDEV.S(B5:H5) -> 13.019939 | J5: =I5/K5 -> 0.12428152 | K5: =AVERAGE(B5:H5) -> 104.76167 | L5: =IF(J5>0.15,"High Inconsistency","Acceptable") -> Acceptable
A6: Roadster | B6: =AVERAGEIFS(Brand_size_analysis!$C:$C, Brand_size_analysis!$A:$A, $A6, Brand_size_analysis!$B:$B, B$1) -> 91.216667 | C6: =AVERAGEIFS(Brand_size_analysis!$C:$C, Brand_size_analysis!$A:$A, $A6, Brand_size_analysis!$B:$B, C$1) -> 97.5 | D6: =AVERAGEIFS(Brand_size_analysis!$C:$C, Brand_size_analysis!$A:$A, $A6, Brand_size_analysis!$B:$B, D$1) -> 103.43333 | E6: =AVERAGEIFS(Brand_size_analysis!$C:$C, Brand_size_analysis!$A:$A, $A6, Brand_size_analysis!$B:$B, E$1) -> 109.75 | F6: =AVERAGEIFS(Brand_size_analysis!$C:$C, Brand_size_analysis!$A:$A, $A6, Brand_size_analysis!$B:$B, F$1) -> 119.63333 | G6: =AVERAGEIFS(Brand_size_analysis!$C:$C, Brand_size_analysis!$A:$A, $A6, Brand_size_analysis!$B:$B, G$1) -> 127 | I6: =_xlfn.STDEV.S(B6:H6) -> 13.506548 | J6: =I6/K6 -> 0.12495779 | K6: =AVERAGE(B6:H6) -> 108.08889 | L6: =IF(J6>0.15,"High Inconsistency","Acceptable") -> Acceptable
A7: Mast & Harbour | B7: =AVERAGEIFS(Brand_size_analysis!$C:$C, Brand_size_analysis!$A:$A, $A7, Brand_size_analysis!$B:$B, B$1) -> 101.16667 | C7: =AVERAGEIFS(Brand_size_analysis!$C:$C, Brand_size_analysis!$A:$A, $A7, Brand_size_analysis!$B:$B, C$1) -> 106.93333 | D7: =AVERAGEIFS(Brand_size_analysis!$C:$C, Brand_size_analysis!$A:$A, $A7, Brand_size_analysis!$B:$B, D$1) -> 112.86667 | E7: =AVERAGEIFS(Brand_size_analysis!$C:$C, Brand_size_analysis!$A:$A, $A7, Brand_size_analysis!$B:$B, E$1) -> 118.8 | I7: =_xlfn.STDEV.S(B7:H7) -> 7.5955335 | J7: =I7/K7 -> 0.069086942 | K7: =AVERAGE(B7:H7) -> 109.94167 | L7: =IF(J7>0.15,"High Inconsistency","Acceptable") -> Acceptable
A8: WROGN | B8: =AVERAGEIFS(Brand_size_analysis!$C:$C, Brand_size_analysis!$A:$A, $A8, Brand_size_analysis!$B:$B, B$1) -> 102.6 | C8: =AVERAGEIFS(Brand_size_analysis!$C:$C, Brand_size_analysis!$A:$A, $A8, Brand_size_analysis!$B:$B, C$1) -> 107.7 | D8: =AVERAGEIFS(Brand_size_analysis!$C:$C, Brand_size_analysis!$A:$A, $A8, Brand_size_analysis!$B:$B, D$1) -> 112.8 | E8: =AVERAGEIFS(Brand_size_analysis!$C:$C, Brand_size_analysis!$A:$A, $A8, Brand_size_analysis!$B:$B, E$1) -> 119.15 | F8: =AVERAGEIFS(Brand_size_analysis!$C:$C, Brand_size_analysis!$A:$A, $A8, Brand_size_analysis!$B:$B, F$1) -> 125.5 | I8: =_xlfn.STDEV.S(B8:H8) -> 9.0671109 | J8: =I8/K8 -> 0.079851263 | K8: =AVERAGE(B8:H8) -> 113.55 | L8: =IF(J8>0.15,"High Inconsistency","Acceptable") -> Acceptable
A9: HERE & NOW | B9: =AVERAGEIFS(Brand_size_analysis!$C:$C, Brand_size_analysis!$A:$A, $A9, Brand_size_analysis!$B:$B, B$1) -> 93.133333 | C9: =AVERAGEIFS(Brand_size_analysis!$C:$C, Brand_size_analysis!$A:$A, $A9, Brand_size_analysis!$B:$B, C$1) -> 99.05 | D9: =AVERAGEIFS(Brand_size_analysis!$C:$C, Brand_size_analysis!$A:$A, $A9, Brand_size_analysis!$B:$B, D$1) -> 104.15 | E9: =AVERAGEIFS(Brand_size_analysis!$C:$C, Brand_size_analysis!$A:$A, $A9, Brand_size_analysis!$B:$B, E$1) -> 109.225 | F9: =AVERAGEIFS(Brand_size_analysis!$C:$C, Brand_size_analysis!$A:$A, $A9, Brand_size_analysis!$B:$B, F$1) -> 114.33333 | I9: =_xlfn.STDEV.S(B9:H9) -> 8.316933 | J9: =I9/K9 -> 0.079987174 | K9: =AVERAGE(B9:H9) -> 103.97833 | L9: =IF(J9>0.15,"High Inconsistency","Acceptable") -> Acceptable
A14: Brand | B14: CV
A15: Puma | B15: 0.1825
A16: Adidas | B16: 0.1253
A17: Roadster | B17: 0.125
A18: H&M | B18: 0.1243
A19: Levi’s | B19: 0.1121
A20: HERE & NOW | B20: 0.08
A21: WROGN | B21: 0.0799
A22: Mast & Harbour | B22: 0.0691
